Workbook

Sheet Sheet10
A1: TAG NUMBER | B1: Previous Company ID | D1: Category | E1: Location | F1: Description | G1: Serial Number or IMEI | H1: Additional Accessories | I1: Department
A2: MON001 | B2: - | C2: Monitor | D2: Moeketse Kuenane | E2: O&M Section | F2: Dell 24 FHD | G2: CN-ORGF30-WSLOO-14Q-HL1L-A04 | H2: HDMI Cable | I2: Operations and Maintenance
A3: MON002 | B3: 0081 | C3: Monitor | D3: Rasekeiti Mohlomi | E3: O&M Section | F3: Dell 24 FHD | G3: 406SAAB0B968 | H3: HDMI Cable Ethernet cable | I3: Operations and Maintenance
A4: MON003 | B4: 0420 | C4: Monitor | D4: Neo Serobanyane | E4: O&M Section | F4: Dell 24 FHD | G4: 038969100343082020H | H4: HDMI Cable Ethernet cable | I4: Operations and Maintenance
A5: MON004 | B5: - | C5: Monitor | D5: Matthew Orosz | E5: EHS Section | F5: Dell 24 FHD | G5: CN-0XXCGP-TV200-26H-DCSV-A03 | I5: -
A6: MON005 | B6: 0381-B | C6: Monitor | D6: Jonase Nthunya | E6: EHS Section | F6: Viewsonic | G6: V86184340487 | I6: EHS
A7: MON006 | B7: - | C7: Monitor | D7: Tlhokomelo Kikine | E7: EE and IT Area | F7: Dell 24 FHD | G7: CN-0WWWVVK-B0Z00-15S-0PAB-A00 | H7: HDMI Cable | I7: IT
A8: MON007 | B8: - | C8: Monitor | D8: Tumisang Mathaba | E8: Production Area | F8: Dell 24 FHD | I8: Production
A9: MON008 | B9: EE08 | C9: Monitor | D9: Rantsane Tsosane | E9: Procurement Section | F9: Samsung | G9: 4L24H7BR401226Z | H9: Keyboard,VGA,Mouse Mounted Multi Plug, Ethernet Cable | I9: Procurement
A10: MON009 | B10: - | C10: Monitor | D10: Mlanjeni Tikiso | E10: PM Section | F10: Samsung | G10: 4L24H7BR401267M | I10: PM
A11: MON010 | B11: EE06 | C11: Monitor | D11: lap | E11: PM Section | F11: Philips | G11: XVDA2116003944 | I11: PM
A12: MON011 | B12: EE09 | C12: Monitor | D12: Teboho Molantoa | E12: PM Section | F12: Viewsonic | G12: V86184340506 | I12: PM
A13: MON012 | B13: 0423-D | C13: Monitor | D13: Katleho Pule | E13: PM Section | F13: Telefunken | G13: 039868-102156-012021J | I13: PM
A14: MON013 | B14: AD003 | C14: Monitor | D14: Moliehi Lepheane | E14: Admin and Finance | F14: Telefunken | G14: 5C7A53BD-C438-46F3-A042-0EBC98F4743E | I14: Admin
A15: MON014 | B15: AD002 | C15: Monitor | D15: Refiloe Ramalefane | E15: Admin and Finance | F15: Telefunken | G15: F1782735-54E5-469A-92C9-22A543C566E8 | I15: Finance
A16: MON015 | B16: AD001 | C16: Monitor | D16: Palama Kelepa | E16: Admin and Finance | F16: Dell 24 FHD | G16: CN-0WWVVK-BOZ00-158-0B2B-A00 | I16: Finance
A17: MON016 | B17: EHS-05 | C17: Monitor | D17: Mojabeng Sonopo | E17: EE and IT Area | F17: Dell 24 FHD | G17: CN-0WWVVK-BOZ00-155-0P88-A00 | I17: PM
A18: MON017 | B18: EE001 | C18: Monitor | D18: Josias Molomo | E18: EE and IT Area | F18: Dell 24 FHD | G18: CN-0RGF30-WSL00-14Q-HLNL-A04 | I18: EE
A19: MON018 | B19: - | C19: Monitor | D19: Motlatsi Manka | E19: EE and IT Area | F19: Dell 24 FHD | G19: CN-011PWC-WSL00-1AP-AQVP-A04 | I19: EE
A20: MON019 | B20: EE06 | C20: Monitor | D20: Thabang Hatlane | E20: EE and IT Area | F20: Dell 24 FHD | G20: CN-0WWVVK-BOZ00-155-2C6B-A00 | I20: EE
A21: MON020 | B21: EE05 | C21: Monitor | D21: Motebang Lekhooana | E21: EE and IT Area | F21: Dell 24 FHD | G21: CN-0RGF30-WSL00-14Q-HL1L-A04 | I21: IT
... A25: MON024 | B25: EE07 | C25: Monitor | D25: Lichaba West | E25: Production Area | F25: Dell 24 FHD | G25: CN-0WWVVK-BOZ00-15S-06AB-A00 | I25: Production
A26: MON025 | B26: EE02 | C26: Monitor | D26: - | I26: Production
A27: MON026 | B27: P001 | C27: Monitor | D27: Production | E27: Production Area | F27: Telefucken | I27: Production
A28: MON027 | B28: - | C28: Monitor | D28: Thabo Monoto | E28: EE and IT Area | F28: Dell 24 FHD | G28: CN-011PWC-WSL00-1B5-379B-A05 | I28: EE
A29: MON028 | B29: - | C29: Monitor | D29: unassigned | E29: EE and IT Area | F29: Dell 24 FHD | G29: CN-0XXCGP-TV200-26H-057V-A03
A30: MON029 | B30: - | C30: Monitor | D30: Kananelo Mokobori | E30: Production Area | F30: Dell 24 FHD | G30: CN-0XXCGP-TV200-26H-094V-A03
A31: MON030 | B31: - | C31: Monitor | D31: Tumelo Tshabalala | E31: EE and IT Area | F31: Dell 24 FHD | G31: CN-0XXCGP-TV200-26H-055V-A03
A32: MON031 | B32: - | C32: Monitor | D32: unassigned | E32: EE and IT Area | F32: Dell 24 FHD | G32: CN-0XXCGP-TV200-26H-08MV-A03
A33: MON032 | B33: - | C33: Monitor | D33: Operations and Maintenance | E33: O&M Section | F33: AIWA | H33: HDMI | I33: O&M
A34: MON033 | B34: - | C34: Monitor | D34: Operations and Maintenance | E34: O&M Section | F34: AIWA | I34: O&M
A35: MON034 | B35: - | C35: Monitor | D35: Operations and Maintenance | E35: O&M Section | F35: AIWA | I35: O&M
A36: MON035 | B36: - | C36: Monitor | D36: CCTV | E36: Admin and Finance | I36: Finance
A37: MON036 | B37: - | C37: Monitor | D37: unassigned | E37: Dead | F37: Dell 24 FHD
A38: MON037 | B38: - | C38: Monitor | D38: unassigned | E38: Dead | F38: Telefucken
A39: MON038 | B39: - | C39: Monitor | D39: Keketso Mosenene | E39: finance | F39: meccer | I39: finance
A45: CPU001 | B45: 0444 | C45: CPU | D45: Operations and Maintenance | E45: O&M Section | F45: HP | I45: O&M
A46: CPU002 | B46: CP04 | C46: CPU | D46: Operations and Maintenance | E46: O&M Section | F46: HP | G46: 2UA2490668V | I46: O&M
A47: CPU003 | B47: CP02 | C47: CPU | D47: Lineo Mosoenyane | E47: Procurement Section | F47: HP | G47: MXL33922C46 | I47: Procurement
A48: CPU004 | B48: D-008 | C48: CPU | D48: Rantsane Tsosane | E48: Procurement Section | F48: HP | G48: 2UA3090QN4 | I48: Procurement
...

Sheet Inventory
A1: Timestamp | B1: Company ID | C1: State | D1: Phone Number | E1: Category | F1: Assigned to (Full names of assignee) | G1: Quantity | H1: Location | I1: Description | J1: Serial Number | K1: Device Setup(any software/ application installed) | L1: Additional Accessories | M1: Department
B3: OnM Deparment Desktop | E3: Desktop | F3: OnM Deparment Desktop | G3: 1 | H3: OnM | I3: Screen Displays | J3: D-003 | K3: Microsoft Office, Chrome, PDF Reader, Google Earth Pro | L3: mouse, Keyboard, 3 Monitors and their Remotes, 2 Display Devices, WiFi Dongle, Multiplug | M3: Operations and Maintenance
B4: LOG01 | E4: Mouse | F4: Mojabeng Sonopo | G4: 1 | H4: EE Area | I4: Logitech Mouse | J4: 2125HSO4PYF8 | L4: Mouse Pad | M4: EE
B5: LOG02 | E5: Mouse | F5: Thabo Monoto | G5: 1 | H5: EE Locker | I5: Logitech Mouse | J5: 2115HS07BET8 | K5: - | M5: EE
B6: LOG03 | E6: Mouse | F6: Rasekeiti Mohlomi | G6: 1 | H6: EE Locker | I6: Logitech Mouse | J6: 2048HS018YP8 | K6: - | M6: EE
B7: LOG04 | E7: Mouse | F7: - | G7: 1 | H7: EE Locker | I7: Logitech mouse | J7: 2045HSO05VBV8 | K7: - | L7: - | M7: EE
B8: CHR01 | E8: Charger | F8: Mojabeng Sonopo | G8: 1 | H8: EE Locker | I8: HP charger | J8: WCQAAAOC1R5YICZ | K8: - | L8: - | M8: EE
B9: CHR02 | E9: charger | F9: - | G9: 1 | H9: EE Locker | I9: HP charger | J9: WCQAAOC1R4SFX9 | K9: - | L9: - | M9: EE
B10: CHR03 | E10: charger | F10: Rasekeiti Mohlomi | G10: 1 | H10: EE Locker | I10: HP charger | J10: WBBXR0ALAZY6VS | K10: - | L10: - | M10: EE
B11: CHRO4 | E11: charger | F11: - | G11: 1 | H11: EE Locker | I11: HP charger | J11: WCQAAOC1R8HD0H | K11: - | L11: - | M11: EE
B12: KB01 | E12: keyboard | F12: Mojabeng Sonopo | G12: 1 | H12: EE Locker | I12: Keyboard | K12: - | L12: - | M12: EE
B13: KB02 | E13: keyboard | F13: Thabo Monoto | G13: 1 | H13: EE locker | I13: keyboard | K13: - | L13: - | M13: EE
B14: KB03 | E14: Keyboard | F14: Rasekeiti Mohlomi | G14: 1 | H14: EE Locker | I14: keyboard | K14: - | L14: - | M14: EE
B15: KB04 | E15: Keyboard | F15: - | G15: 1 | H15: EE locker | I15: keyboard | K15: - | L15: - | M15: EE
B16: CP01 | E16: CPU | F16: Mojabeng Sonopo | G16: 1 | H16: EE locker | I16: HP | J16: MXL2501N43 | K16: - | L16: Wifi Adapter Display to HDMI | M16: EE
B17: CP02 | E17: CPU | F17: Lineo | G17: 1 | H17: Procument | I17: HP CPU | J17: MXL3392C46 | K17: - | L17: Display to HDMI Keyboard(KB02) Wifi Adapter Extension Cord Multi Plug Mouse (LOG02) Universal Adapter | M17: Procurement
B18: CP03 | E18: Desktop | F18: - | G18: 1 | H18: EE locker | I18: Desktop (cpu) | J18: MXL31601BY | K18: - | L18: - | M18: EE
B19: CP04 | E19: Desktop | F19: - | G19: 1 | H19: EE Locker | I19: Desktop (cpu) | J19: 2UA2490668V | K19: - | L19: - | M19: EE
B20: LDS00 | E20: Loudspeaker | F20: - | G20: 1 | H20: EE locker | I20: loudspeaker | J20: - | K20: - | L20: - | M20: EE
B21: RBP00 | E21: Raspberry pie | F21: Thabo Monoto | G21: 1 | H21: EE locker | I21: Raspberry pie | J21: 2019AJI0494 | K21: - | L21: - | M21: EE
B22: SML001 | E22: Smart Locker | F22: - | G22: 1 | H22: EE locker | I22: smart locker | J22: - | K22: - | L22: - | M22: Facilities
B23: SML002 | E23: Smart Locker | F23: - | G23: 1 | H23: EE Locker | I23: smart locker | J23: - | K23: - | L23: - | M23: Facilities
B24: SML003 | E24: smart locker | F24: - | G24: 1 | H24: EE locker | I24: smart locker | J24: - | K24: - | L24: - | M24: Facilities
B25: SML004 | E25: Smart locker | F25: - | G25: 1 | H25: EE locker | I25: smart locker | J25: - | K25: - | L25: - | M25: Facilities
B26: SML 005 | E26: smart locker | F26: - | G26: 1 | H26: EE locker | I26: smart locker | J26: - | K26: - | L26: - | M26: Facilities
B27: PMP001 | E27: car pump | F27: - | G27: 1 | H27: EE locker | I27: car pump | J27: - | K27: - | L27: - | M27: Fleet
B28: BULB001 | E28: KS Turn replacement bulb | F28: - | G28: 2 | H28: EE locker | I28: KS Turn replacement bulb | J28: - | K28: - | L28: - | M28: EE
B29: Untagged/None
B30: Surf -1 | C30: =IF(B:B='Check in'!B:B,"Usable",IF('Check in'!D:D="Good Condition","Usable","Not Usable")) -> Not Usable | D30: 57253337 | E30: Phone | F30: Lost | G30: 1 | H30: Surf -1 | J30: 359137090447944 | M30: Fleet
B31: Main | C31: =IF(B:B='Check in'!B:B,"Usable",IF('Check in'!D:D="Good Condition","Usable","Not Usable")) -> Not Usable | D31: 57755403 | E31: Phone | F31: Phoka Raphoka | G31: 1 | H31: HQ | J31: 359137090448892 | L31: Charger | M31: Procurement
B32: X-trail Phone | C32: =IF(AND('Check in'!B:B=B32,'Check in'!D:D="Good Condition"),"Not Usable","Usable") -> Usable | D32: 50002953 | E32: Phone | F32: Replaced | G32: 1 | H32: X-trail | J32: 357441100338545 | M32: Fleet
B33: Truck 36 Phone | C33: =IF(AND('Check in'!B:B=B33,'Check in'!D:D="Good Condition"),"Not Usable","Usable") -> Usable | D33: 57517692 | E33: Phone | F33: Replaced | G33: 1 | H33: Truck 36 Phone | J33: 357441100288138 | M33: Fleet
B34: SMS gateway | C34: =IF(AND('Check in'!B:B=B34,'Check in'!D:D="Good Condition"),"Not Usable","Usable") -> Usable | D34: 50329017 | E34: Phone | F34: EHS Department | G34: 1 | H34: O&M Department | I34: Samsung A02,Blue,6.5",32GB | J34: 867173041276079 | M34: O&M
B35: Dev & Test Phone | C35: =IF(AND('Check in'!B:B=B35,'Check in'!D:D="Good Condition"),"Not Usable","Usable") -> Usable | D35: 63557950 | E35: Phone | F35: EE Department | G35: 1 | H35: IT Locker | J35: 864931055950225
B36: Makebe Field Site 0363 | C36: =IF(AND('Check in'!B:B=B36,'Check in'!D:D="Good Condition"),"Usable","Not Usable") -> Not Usable | D36: 59436506 | E36: Phone | F36: Teboho Noko | G36: 1 | H36: Makebe Field Site 0363 | J36: 355622107185433 | M36: Reticulation
B37: Survey Phone 0369 | C37: =IF(AND('Check in'!B:B=B37,'Check in'!D:D="Good Condition"),"Usable","Not Usable") -> Not Usable | D37: 56434364 | E37: Phone | F37: Broken | G37: 1 | H37: IT Locker | I37: Azumi v5+, 5.0" Screen Broken ,replacement parts currently unavailable. | J37: 357441100355838 | M37: EHS
B38: Survey Phone 0370 | D38: 58488198 | E38: Phone | F38: Replaced | G38: 1 | H38: Survey Phone 0370 | J38: 357441100356166
B39: Pajero | C39: =IF(AND('Check in'!B:B=B39,'Check in'!D:D="Good Condition"),"Usable","Not Usable") -> Not Usable | D39: 56660005 | E39: Phone | F39: Fleet Department | G39: 1 | H39: Pajero | J39: 358846169697376 | M39: Fleet
B40: Surf -2 0373 | C40: =IF(AND('Check in'!B:B=B40,'Check in'!D:D="Good Condition"),"Usable","Not Usable") -> Not Usable | D40: 58757576 | E40: Phone | F40: Fleet Department | G40: 1 | H40: IT Locker | J40: 482990508507030510 | M40: Fleet
B41: Customer Support | C41: =IF(AND('Check in'!B:B=B41,'Check in'!D:D="Good Condition"),"Usable","Not Usable") -> Not Usable | D41: 58342168 | E41: Phone | F41: O&M Department | G41: 1 | H41: O&M Department | J41: 511008240007080
...

Sheet Untaggable
A1: Chargers | B1: Quantity | D1: Cables and Adapters | E1: Quantity | G1: Tools | H1: Quantity | J1: Equipment | K1: Quantity
A2: HP | B2: 6 | D2: Kenable Power Cable | E2: 22 | G2: cctv cameras | H2: 13 | J2: Label Maker | K2: 2
A3: Dell | B3: 5 | D3: 3-pin Power Cable | E3: 5 | G3: NVR | H3: 1 | J3: Tablets Covers model 7 | K3: 27
A4: TV | B4: 1 | D4: Ethernet | E4: 7 | G4: Flat Screw Driver | H4: 2 | J4: Tablets Screen Protectors | K4: 10
A5: Blackberry | B5: 1 | D5: HDMI | E5: 5 | G5: Blades Set | H5: 1 | J5: Phone covers | K5: 47
A6: Asus | B6: 1 | D6: Vga | E6: 7 | G6: Side Cutter | H6: 2 | J6: Phone Screen Protectors | K6: 47
D7: Display to HDMI | E7: 8 | G7: 11.5" Drill Bit Set | H7: 1 | J7: Flash Drive | K7: 1
D8: VGA to HDMI | E8: 5 | G8: Wire Strippers | H8: 3 | J8: Power Banks | K8: 1
D9: Ethernet Adapter | E9: 1 | G9: Stripping Gun | H9: 2
D10: Extension Cord | E10: 1 | G10: Pliers | H10: 3
D11: Universal Adapters | E11: 10 | G11: Crimping tool | H11: 1
D12: 2 Pin Plug Adapter | E12: 3 | G12: Vice Grip | H12: 1
D13: Aux Cable | E13: 1 | G13: Nail Stripper/Puller | H13: 1
D14: Male USB-USB | E14: 3 | G14: Soldering Iron Sucker | H14: 1
D15: Female USB-USB | E15: 2 | G15: Load Balance/Batrpas | H15: 1
D16: USB B 2.0 | E16: 7 | G16: Measuring Tape | H16: 1
D17: Stereo Adapters | E17: 2 | G17: Chisel | H17: 1
D18: Victron Energy Power Cables | E18: 1 | G18: Solar Panels | H18: 4
D19: Victron Energy Direct-USB | E19: 1 | G19: G3 Fatbox Modem | H19: 1
D20: Earphone-mic (K-type) | E20: 6 | G20: POE Switch | H20: 1
... D27: PC Tire Cable | E27: 1 | G27: Thermal Sensors | H27: 2
D28: Wifi Adapter | G28: DI-158U | H28: 1
G29: Expansion Module | H29: 1
G30: SDM120 | H30: 1
G31: SDM530 | H31: 1
G32: LED display | H32: 1
G33: Transducer | H33: 1
G34: Speedometer | H34: 1
G35: Programmable K-Factor Scaler | H35: 1
G36: Modified Sinewave Inverter | H36: 1
G37: Tachometer | H37: 1
G38: DC-DC converter | H38: 2
G39: Crocodile clips | H39: 1

Sheet Detailed Approval Records Forme
A1: Timestamp | B1: Response Id | C1: Request # | D1: Revision # | E1: Overall Status | F1: Requestor | G1: Edit Response Url | H1: Total Recipients | I1: Participant Ids | J1: Recipient 1 | K1: Recipient 1 Status | L1: Recipient 1 Issue Date | M1: Recipient 1 Response Date | N1: Recipient 1 Comment | O1: Recipient 1 Settings | P1: Recipient 2 | Q1: Recipient 2 Status | R1: Recipient 2 Issue Date | S1: Recipient 2 Response Date | T1: Recipient 2 Comment | U1: Recipient 2 Settings | V1: Recipient 3 | W1: Recipient 3 Status | X1: Recipient 3 Issue Date | Y1: Recipient 3 Response Date | Z1: Recipient 3 Comment | AA1: Recipient 3 Settings | AB1: Recipient 4 | AC1: Recipient 4 Status | AD1: Recipient 4 Issue Date | AE1: Recipient 4 Response Date | AF1: Recipient 4 Comment | AG1: Recipient 4 Settings | AH1: Recipient 5 | AI1: Recipient 5 Status | AJ1: Recipient 5 Issue Date | AK1: Recipient 5 Response Date | AL1: Recipient 5 Comment | AM1: Recipient 5 Settings | AN1: Recipient 6 | AO1: Recipient 6 Status | AP1: Recipient 6 Issue Date | AQ1: Recipient 6 Response Date | AR1: Recipient 6 Comment | AS1: Recipient 6 Settings | AT1: Recipient 7 | AU1: Recipient 7 Status | AV1: Recipient 7 Issue Date | AW1: Recipient 7 Response Date | AX1: Recipient 7 Comment | AY1: Recipient 7 Settings | AZ1: Recipient 8 | BA1: Recipient 8 Status | BB1: Recipient 8 Issue Date | BC1: Recipient 8 Response Date | BD1: Recipient 8 Comment | BE1: Recipient 8 Settings | BF1: Recipient 9 | BG1: Recipient 9 Status | BH1: Recipient 9 Issue Date | BI1: Recipient 9 Response Date | BJ1: Recipient 9 Comment | BK1: Recipient 9 Settings | BL1: Recipient 10 | BM1: Recipient 10 Status | BN1: Recipient 10 Issue Date | BO1: Recipient 10 Response Date | BP1: Recipient 10 Comment | BQ1: Recipient 10 Settings
A2: 44775.382 | B2: 2_ABaOnue4Eu6_Ad35HQhEU7MQSDxx17F95eiNQfCTzbj_F8Xk82lcrT_WxsY8_naD6h68x0g | C2: 1 | D2: 0 | E2: Complete | G2: https://docs.google.com/forms/d/e/1FAIpQLSfozIV5FQqcQNjQaUk40v9z-N0PHEZT8xM98Ndh72nkn88rVw/viewform?edit2=2_ABaOnue4Eu6_Ad35HQhEU7MQSDxx17F95eiNQfCTzbj_F8Xk82lcrT_WxsY8_naD6h68x0g | H2: 1 | I2: {"Recipients":[{"it-support@1pwrafrica.com":"9e05d7"}]} | J2: it-support@1pwrafrica.com | K2: Approved | L2: 44775.382 | M2: 44775.383 | N2: Cool | O2: {"Order":1,"Role":"Needs to Approve"}
A3: 44775.388 | B3: 2_ABaOnudjurLp6LV8QSahFYxPW0qh8ygNrZhaYXI-VylRQ5sgRXEOmiHoqS6LhnSUJF_A7Mc | C3: 2 | D3: 0 | E3: Complete | G3: https://docs.google.com/forms/d/e/1FAIpQLSfozIV5FQqcQNjQaUk40v9z-N0PHEZT8xM98Ndh72nkn88rVw/viewform?edit2=2_ABaOnudjurLp6LV8QSahFYxPW0qh8ygNrZhaYXI-VylRQ5sgRXEOmiHoqS6LhnSUJF_A7Mc | H3: 1 | I3: {"Recipients":[{"it-support@1pwrafrica.com":"563d42"}]} | J3: it-support@1pwrafrica.com | K3: Approved | L3: 44775.388 | M3: 44775.388 | N3: Will bring it to you sir, Regards Motebang | O3: {"Order":1,"Role":"Needs to Approve"}
A4: 44775.442 | B4: 2_ABaOnud-xDqTyBXea4vq8CNk3uI-O3hu3OSTGrPINCeMtBidsMMgHkutA8HFzIcq2Nxq4R0 | C4: 3 | D4: 0 | E4: Complete | G4: https://docs.google.com/forms/d/e/1FAIpQLSfozIV5FQqcQNjQaUk40v9z-N0PHEZT8xM98Ndh72nkn88rVw/viewform?edit2=2_ABaOnud-xDqTyBXea4vq8CNk3uI-O3hu3OSTGrPINCeMtBidsMMgHkutA8HFzIcq2Nxq4R0 | H4: 1 | I4: {"Recipients":[{"it-support@1pwrafrica.com":"5b1744"}]} | J4: it-support@1pwrafrica.com | K4: Approved | L4: 44775.442 | M4: 44775.473 | N4: Noted ntate, But the problem for now is delay because we will have to ask Matt to come with it from the US. Regards, Motebang | O4: {"Order":1,"Role":"Needs to Approve"}
A5: 44775.479 | B5: 2_ABaOnue1kh6j4-3aIPvR8566wUur47LHHE5vyUmInFPBGyMbbD6tWa9FKc7hXC1FUpeLMJQ | C5: 4 | D5: 0 | E5: Complete | G5: https://docs.google.com/forms/d/e/1FAIpQLSfozIV5FQqcQNjQaUk40v9z-N0PHEZT8xM98Ndh72nkn88rVw/viewform?edit2=2_ABaOnue1kh6j4-3aIPvR8566wUur47LHHE5vyUmInFPBGyMbbD6tWa9FKc7hXC1FUpeLMJQ | H5: 1 | I5: {"Recipients":[{"it-support@1pwrafrica.com":"30deeb"}]} | J5: it-support@1pwrafrica.com | K5: Approved | L5: 44775.479 | M5: 44775.48 | N5: test | O5: {"Order":1,"Role":"Needs to Approve"}
A6: 44775.49 | B6: 2_ABaOnudEJTUEVNc2CSaWnLue_fW9mhxr6KdaaPeBFRitTJOrR4RIsknyxbRjEXZuaxok4kU | C6: 5 | D6: 0 | E6: Complete | G6: https://docs.google.com/forms/d/e/1FAIpQLSfozIV5FQqcQNjQaUk40v9z-N0PHEZT8xM98Ndh72nkn88rVw/viewform?edit2=2_ABaOnudEJTUEVNc2CSaWnLue_fW9mhxr6KdaaPeBFRitTJOrR4RIsknyxbRjEXZuaxok4kU | H6: 1 | I6: {"Recipients":[{"it-support@1pwrafrica.com":"9957f6"}]} | J6: it-support@1pwrafrica.com | K6: Approved | L6: 44775.49 | M6: 44775.492 | N6: Noted, will discuss this with my colleagues for what need to be done ASAP, Regards, Motebang | O6: {"Order":1,"Role":"Needs to Approve"}
A7: 44775.616 | B7: 2_ABaOnuca4xu6hq5XvIc13-ntaT6bMlDoY4n_WcD_w4XPC_MVgzUsj1wUop-IjKrK3pKJxDk | C7: 6 | D7: 0 | E7: In progress | G7: https://docs.google.com/forms/d/e/1FAIpQLSfozIV5FQqcQNjQaUk40v9z-N0PHEZT8xM98Ndh72nkn88rVw/viewform?edit2=2_ABaOnuca4xu6hq5XvIc13-ntaT6bMlDoY4n_WcD_w4XPC_MVgzUsj1wUop-IjKrK3pKJxDk | H7: 1 | I7: {"Recipients":[{"it-support@1pwrafrica.com":"26d992"}]} | J7: it-support@1pwrafrica.com | K7: Current | L7: 44775.616 | O7: {"Order":1,"Role":"Needs to Approve"}
A8: 44775.703 | B8: 2_ABaOnudHB8wKML1X73pfGpgETyKbERSBy5E_SSv_y90-USBEPJ2DN4cjujjLAhG9WW52j_k | C8: 7 | D8: 0 | E8: Complete | G8: https://docs.google.com/forms/d/e/1FAIpQLSfozIV5FQqcQNjQaUk40v9z-N0PHEZT8xM98Ndh72nkn88rVw/viewform?edit2=2_ABaOnudHB8wKML1X73pfGpgETyKbERSBy5E_SSv_y90-USBEPJ2DN4cjujjLAhG9WW52j_k | H8: 1 | I8: {"Recipients":[{"it-support@1pwrafrica.com":"2df96b"}]} | J8: it-support@1pwrafrica.com | K8: Approved | L8: 44775.703 | M8: 44775.706 | O8: {"Order":1,"Role":"Needs to Approve"}
A9: 44776.49 | B9: 2_ABaOnucbmw1RilpVWedpHjBFAUNYMOXo2q_OnOhVbdxYZSpyb1afIMDLrxKBY37Zvjc5Xic | C9: 8 | D9: 0 | E9: Complete | G9: https://docs.google.com/forms/d/e/1FAIpQLSfozIV5FQqcQNjQaUk40v9z-N0PHEZT8xM98Ndh72nkn88rVw/viewform?edit2=2_ABaOnucbmw1RilpVWedpHjBFAUNYMOXo2q_OnOhVbdxYZSpyb1afIMDLrxKBY37Zvjc5Xic | H9: 1 | I9: {"Recipients":[{"it-support@1pwrafrica.com":"99c6aa"}]} | J9: it-support@1pwrafrica.com | K9: Approved | L9: 44776.49 | M9: 44776.51 | N9: I'm on it, Will be resolved. Regards, Motebang | O9: {"Order":1,"Role":"Needs to Approve"}
A10: 44776.597 | B10: 2_ABaOnudJzcqFjAG1XvUNWcKlFZeawfyXRSiLHHmz0QhFN40yJkJXoIMRY_6NyWx0uxXGU1A | C10: 9 | D10: 0 | E10: Complete | G10: https://docs.google.com/forms/d/e/1FAIpQLSfozIV5FQqcQNjQaUk40v9z-N0PHEZT8xM98Ndh72nkn88rVw/viewform?edit2=2_ABaOnudJzcqFjAG1XvUNWcKlFZeawfyXRSiLHHmz0QhFN40yJkJXoIMRY_6NyWx0uxXGU1A | H10: 1 | I10: {"Recipients":[{"it-support@1pwrafrica.com":"f82741"}]} | J10: it-support@1pwrafrica.com | K10: Approved | L10: 44776.597 | M10: 44776.671 | N10: We will let people responsible for such maintanances resolve that. Tumisang is absent and we do not have a spare multiplug. Regards, Motebang | O10: {"Order":1,"Role":"Needs to Approve"}
A11: 44776.668 | B11: 2_ABaOnufqRSi40ZhvlzspC-Vk8CDJ5RbjEG5ck5Zohcb1QQECiu38SMaTlsAH6VUM4_tRjYY | C11: 10 | D11: 0 | E11: Complete | G11: https://docs.google.com/forms/d/e/1FAIpQLSfozIV5FQqcQNjQaUk40v9z-N0PHEZT8xM98Ndh72nkn88rVw/viewform?edit2=2_ABaOnufqRSi40ZhvlzspC-Vk8CDJ5RbjEG5ck5Zohcb1QQECiu38SMaTlsAH6VUM4_tRjYY | H11: 1 | I11: {"Recipients":[{"it-support@1pwrafrica.com":"411e70"}]} | J11: it-support@1pwrafrica.com | K11: Approved | L11: 44776.668 | M11: 44776.669 | N11: Yes, it has to have it. I will come around to help regarding that. Regards, Motebang | O11: {"Order":1,"Role":"Needs to Approve"}
A12: 44777.413 | B12: 2_ABaOnuczbTnIl-__iv7abFm9k7FdjOi1zpdcVefX2FPV5FjjMl_JdFO5ZLMPwAwYkjdtXWw | C12: 11 | D12: 0 | E12: In progress | G12: https://docs.google.com/forms/d/e/1FAIpQLSfozIV5FQqcQNjQaUk40v9z-N0PHEZT8xM98Ndh72nkn88rVw/viewform?edit2=2_ABaOnuczbTnIl-__iv7abFm9k7FdjOi1zpdcVefX2FPV5FjjMl_JdFO5ZLMPwAwYkjdtXWw | H12: 1 | I12: {"Recipients":[{"it-support@1pwrafrica.com":"54aff5"}]} | J12: it-support@1pwrafrica.com | K12: Current | L12: 44777.413 | O12: {"Order":1,"Role":"Needs to Approve"}
A13: 44777.422 | B13: 2_ABaOnueqMXi5tSqNk49VVxy61YJ-VKr5aAxrZUJjOFqb_g_46CdV0T-WZbtEnCZDtgzeO8U | C13: 12 | D13: 0 | E13: Complete | G13: https://docs.google.com/forms/d/e/1FAIpQLSfozIV5FQqcQNjQaUk40v9z-N0PHEZT8xM98Ndh72nkn88rVw/viewform?edit2=2_ABaOnueqMXi5tSqNk49VVxy61YJ-VKr5aAxrZUJjOFqb_g_46CdV0T-WZbtEnCZDtgzeO8U | H13: 1 | I13: {"Recipients":[{"it-support@1pwrafrica.com":"5a3400"}]} | J13: it-support@1pwrafrica.com | K13: Approved | L13: 44777.422 | M13: 44777.431 | O13: {"Order":1,"Role":"Needs to Approve"}
A14: 44777.49 | B14: 2_ABaOnufC8y503gzhce0cm96FFTNhQ4B3gQSHmVWuB7GGKbEmBHxhecskjENFRVXFCrcFAg4 | C14: 13 | D14: 0 | E14: Complete | G14: https://docs.google.com/forms/d/e/1FAIpQLSfozIV5FQqcQNjQaUk40v9z-N0PHEZT8xM98Ndh72nkn88rVw/viewform?edit2=2_ABaOnufC8y503gzhce0cm96FFTNhQ4B3gQSHmVWuB7GGKbEmBHxhecskjENFRVXFCrcFAg4 | H14: 1 | I14: {"Recipients":[{"it-support@1pwrafrica.com":"891ef4"}]} | J14: it-support@1pwrafrica.com | K14: Approved | L14: 44777.49 | M14: 44777.708 | N14: Ntate Jonase, your request is noted but we currently do not have available laptops in the office. We will allocate you one when they are here. Regards, Motebang | O14: {"Order":1,"Role":"Needs to Approve"}
A15: 44781.49 | B15: 2_ABaOnud6vK1U6ocPiYV0eHtp-aD1Jy8R1fHifm-izkmhVVHkRglaSD2-vtCjPj9xbBq4Rdg | C15: 14 | D15: 0 | E15: In progress | G15: https://docs.google.com/forms/d/e/1FAIpQLSfozIV5FQqcQNjQaUk40v9z-N0PHEZT8xM98Ndh72nkn88rVw/viewform?edit2=2_ABaOnud6vK1U6ocPiYV0eHtp-aD1Jy8R1fHifm-izkmhVVHkRglaSD2-vtCjPj9xbBq4Rdg | H15: 1 | I15: {"Recipients":[{"it-support@1pwrafrica.com":"6aa5f5"}]} | J15: it-support@1pwrafrica.com | K15: Current | L15: 44781.49 | O15: {"Order":1,"Role":"Needs to Approve"}
A16: 44781.682 | B16: 2_ABaOnudOZMLJJFL-J0hJ9fD9xL9BhW5VRcHLMgz-KPk7dMliRZ13Z401hRPAh1DGRvKDhoo | C16: 15 | D16: 0 | E16: In progress | G16: https://docs.google.com/forms/d/e/1FAIpQLSfozIV5FQqcQNjQaUk40v9z-N0PHEZT8xM98Ndh72nkn88rVw/viewform?edit2=2_ABaOnudOZMLJJFL-J0hJ9fD9xL9BhW5VRcHLMgz-KPk7dMliRZ13Z401hRPAh1DGRvKDhoo | H16: 1 | I16: {"Recipients":[{"it-support@1pwrafrica.com":"cae945"}]} | J16: it-support@1pwrafrica.com | K16: Current | L16: 44781.682 | O16: {"Order":1,"Role":"Needs to Approve"}
A17: 44783.381 | B17: 2_ABaOnudw6QRmmFAKoeX4tBp05NDTXUo0du2C3cvSQayHH5_r8yCdObh-XUsjGfSF_2RGESY | C17: 16 | D17: 0 | E17: Complete | G17: https://docs.google.com/forms/d/e/1FAIpQLSfozIV5FQqcQNjQaUk40v9z-N0PHEZT8xM98Ndh72nkn88rVw/viewform?edit2=2_ABaOnudw6QRmmFAKoeX4tBp05NDTXUo0du2C3cvSQayHH5_r8yCdObh-XUsjGfSF_2RGESY | H17: 1 | I17: {"Recipients":[{"it-support@1pwrafrica.com":"7fe1b8"}]} | J17: it-support@1pwrafrica.com | K17: Approved | L17: 44783.381 | M17: 44783.381 | O17: {"Order":1,"Role":"Needs to Approve"}
A18: 44783.392 | B18: 2_ABaOnucnGo7KBHFENF-jgHWkiRhzKeeOVndIybRvisjxoiZ745JMg0xP3tbB7GbpiG-hu3A | C18: 17 | D18: 0 | E18: Complete | G18: https://docs.google.com/forms/d/e/1FAIpQLSfozIV5FQqcQNjQaUk40v9z-N0PHEZT8xM98Ndh72nkn88rVw/viewform?edit2=2_ABaOnucnGo7KBHFENF-jgHWkiRhzKeeOVndIybRvisjxoiZ745JMg0xP3tbB7GbpiG-hu3A | H18: 1 | I18: {"Recipients":[{"it-support@1pwrafrica.com":"2cbf20"}]} | J18: it-support@1pwrafrica.com | K18: Approved | L18: 44783.393 | M18: 44783.395 | O18: {"Order":1,"Role":"Needs to Approve"}
A19: 44784.647 | B19: 2_ABaOnufTJdP4DiN6eWLgFMUgRIvWv6lNkwbiCq5_81-Sg4b5zkCtXKMw0CNQ2zZSap1BgrM | C19: 18 | D19: 0 | E19: In progress | G19: https://docs.google.com/forms/d/e/1FAIpQLSfozIV5FQqcQNjQaUk40v9z-N0PHEZT8xM98Ndh72nkn88rVw/viewform?edit2=2_ABaOnufTJdP4DiN6eWLgFMUgRIvWv6lNkwbiCq5_81-Sg4b5zkCtXKMw0CNQ2zZSap1BgrM | H19: 1 | I19: {"Recipients":[{"it-support@1pwrafrica.com":"1aa233"}]} | J19: it-support@1pwrafrica.com | K19: Current | L19: 44784.647 | O19: {"Order":1,"Role":"Needs to Approve"}
A20: 44785.339 | B20: 2_ABaOnuecrtdfp4dLK5zxwKJufZRTJ8GiN4GjM-Yuwya_JnJ7NlIaA4o3lH0dljQXfYsiLrA | C20: 19 | D20: 0 | E20: Complete | G20: https://docs.google.com/forms/d/e/1FAIpQLSfozIV5FQqcQNjQaUk40v9z-N0PHEZT8xM98Ndh72nkn88rVw/viewform?edit2=2_ABaOnuecrtdfp4dLK5zxwKJufZRTJ8GiN4GjM-Yuwya_JnJ7NlIaA4o3lH0dljQXfYsiLrA | H20: 1 | I20: {"Recipients":[{"it-support@1pwrafrica.com":"d7e968"}]} | J20: it-support@1pwrafrica.com | K20: Approved | L20: 44785.339 | M20: 44785.473 | O20: {"Order":1,"Role":"Needs to Approve"}
A21: 44788.661 | B21: 2_ABaOnufWELP0RrG4QN1k4zZsFcckF7oztfwh4edD8w9itsYPC7T3xUH1Ysr6w41F4abFC-8 | C21: 20 | D21: 0 | E21: Complete | G21: https://docs.google.com/forms/d/e/1FAIpQLSfozIV5FQqcQNjQaUk40v9z-N0PHEZT8xM98Ndh72nkn88rVw/viewform?edit2=2_ABaOnufWELP0RrG4QN1k4zZsFcckF7oztfwh4edD8w9itsYPC7T3xUH1Ysr6w41F4abFC-8 | H21: 1 | I21: {"Recipients":[{"it-support@1pwrafrica.com":"124408"}]} | J21: it-support@1pwrafrica.com | K21: Approved | L21: 44788.661 | M21: 44788.673 | O21: {"Order":1,"Role":"Needs to Approve"}

Sheet Detailed Approval Report
A1: # | B1: Unique Request # | C1: Timestamp | D1: Respondent | E1: Final Status | F1: Recipient 1 | J1: Recipient 2 | N1: Recipient 3 | R1: Recipient 4 | V1: Recipient 5 | Z1: Recipient 6 | AD1: Recipient 7 | AH1: Recipient 8 | AL1: Recipient 9 | AP1: Recipient 10
F2: Recipient 1 Email | G2: Recipient 1 Status | H2: Recipient 1 Comment | I2: Recipient 1 Response Date | J2: Recipient 2 Email | K2: Recipient 2 Status | L2: Recipient 2 Comment | M2: Recipient 2 Response Date | N2: Recipient 3 Email | O2: Recipient 3 Status | P2: Recipient 3 Comment | Q2: Recipient 3 Response Date | R2: Recipient 4 Email | S2: Recipient 4 Status | T2: Recipient 4 Comment | U2: Recipient 4 Response Date | V2: Recipient 5 Email | W2: Recipient 5 Status | X2: Recipient 5 Comment | Y2: Recipient 5 Response Date | Z2: Recipient 6 Email | AA2: Recipient 6 Status | AB2: Recipient 6 Comment | AC2: Recipient 6 Response Date | AD2: Recipient 7 Email | AE2: Recipient 7 Status | AF2: Recipient 7 Comment | AG2: Recipient 7 Response Date | AH2: Recipient 8 Email | AI2: Recipient 8 Status | AJ2: Recipient 8 Comment | AK2: Recipient 8 Response Date | AL2: Recipient 9 Email | AM2: Recipient 9 Status | AN2: Recipient 9 Comment | AO2: Recipient 9 Response Date | AP2: Recipient 10 Email | AQ2: Recipient 10 Status | AR2: Recipient 10 Comment | AS2: Recipient 10 Response Date
A3: 29 | C3: 05/31/2022 09:12:44 | D3: cadkikine@gmail.com | E3: Rejected | F3: it-support@1pwrafrica.com | G3: Rejected | I3: 05/31/2022 09:16:32
A4: 30 | C4: 05/31/2022 09:21:09 | D4: cadkikine@gmail.com | E4: Approved | F4: it-support@1pwrafrica.com | G4: Approved | H4: . | I4: 05/31/2022 09:23:00
A5: 31 | C5: 05/31/2022 09:24:35 | D5: cadkikine@gmail.com | E5: In Progress | F5: it-support@1pwrafrica.com
A6: 32 | C6: 05/31/2022 09:25:40 | D6: cadkikine@gmail.com | E6: In Progress | F6: it-support@1pwrafrica.com
A7: 33 | C7: 44718.318 | D7: makhoalinyane@1pwrafrica.com | E7: Approved | F7: it-support@1pwrafrica.com | G7: Approved | I7: 44718.319
A8: 34 | C8: 44718.323 | D8: mosehle@1pwrafrica.com | E8: In Progress | F8: it-support@1pwrafrica.com
A9: 35 | C9: 44718.326 | D9: kubutu@1pwrafrica.com | E9: In Progress | F9: it-support@1pwrafrica.com
A10: 36 | C10: 44718.333 | D10: ernestmoloantoateb@gmail.com | E10: In Progress | F10: it-support@1pwrafrica.com
A11: 37 | C11: 44718.375 | D11: monoane@1pwrafrica.com | E11: In Progress | F11: it-support@1pwrafrica.com
A12: 38 | C12: 44718.605 | D12: leloko@1pwrafrica.com | E12: In Progress | F12: it-support@1pwrafrica.com
A13: 39 | C13: 44718.613 | D13: makhoalinyane@1pwrafrica.com | E13: In Progress | F13: it-support@1pwrafrica.com
A14: 40 | C14: 44718.627 | D14: mosehle@1pwrafrica.com | E14: In Progress | F14: it-support@1pwrafrica.com
A15: 41 | C15: 44748.312 | D15: makoetje@1pwrafrica.com | E15: Approved | F15: it-support@1pwrafrica.com | G15: Approved | I15: 44748.314
A16: 42 | C16: 44748.401 | D16: jopi@1pwrafrica.com | E16: Approved | F16: it-support@1pwrafrica.com | G16: Approved | I16: 44748.401
A17: 43 | C17: 44748.442 | D17: moeketse@1pwrafrica.com | E17: Approved | F17: it-support@1pwrafrica.com | G17: Approved | H17: It is being attended to. | I17: 44748.448
A18: 44 | C18: 44748.529 | D18: jonase@1pwrafrica.com | E18: Approved | F18: it-support@1pwrafrica.com | G18: Approved | I18: 44779.285
A19: 45 | C19: 44779.308 | D19: david@1pwrafrica.com | E19: In Progress | F19: it-support@1pwrafrica.com
A20: 46 | C20: 44779.315 | D20: lichabajameswest@gmail.com | E20: Approved | F20: it-support@1pwrafrica.com | G20: Approved | H20: We are still waiting fopr the laptops that Matt told us he will come with so once they are here we will give you one. | I20: 44779.333
A21: 47 | C21: 44779.618 | D21: mothomotsoanabk@gmail.com | E21: Approved | F21: it-support@1pwrafrica.com | G21: Approved | I21: 44779.127
A22: 48 | C22: 44810.392 | D22: mlanjenijoshua@gmail.com | E22: In Progress | F22: it-support@1pwrafrica.com
A23: 49 | C23: 44840.328 | D23: abele@1pwrafrica.com | E23: Approved | F23: it-support@1pwrafrica.com | G23: Approved | I23: 44840.329
A24: 50 | C24: 44840.5 | D24: phoka@1pwrafrica.com | E24: Approved | F24: it-support@1pwrafrica.com | G24: Approved | I24: 06/13/2022 10:51:02
A25: 51 | C25: 06/13/2022 06:12:21 | D25: thakhisinthabiseng@gmail.com | E25: Approved | F25: it-support@1pwrafrica.com | G25: Approved | I25: 06/13/2022 07:08:18
A26: 52 | C26: 06/13/2022 09:43:16 | D26: maferete@1pwrafrica.com | E26: Rejected | F26: it-support@1pwrafrica.com | G26: Rejected | H26: The parts are currently unavailable. Please make an equipment request. | I26: 06/13/2022 10:05:45
A27: 53 | C27: 06/13/2022 10:08:35 | D27: lichabajameswest@gmail.com | E27: In Progress | F27: it-support@1pwrafrica.com
A28: 54 | C28: 06/13/2022 10:37:04 | D28: morema@1pwrafrica.com | E28: In Progress | F28: it-support@1pwrafrica.com
A29: 55 | C29: 06/13/2022 10:40:54 | D29: morema@1pwrafrica.com | E29: Approved | F29: it-support@1pwrafrica.com | G29: Approved | H29: Noted. We'll have to make a request for it's replacement. | I29: 06/13/2022 10:48:32
A30: 56 | C30: 06/13/2022 10:50:01 | D30: phoka@1pwrafrica.com | E30: In Progress | F30: it-support@1pwrafrica.com
A31: 57 | C31: 06/13/2022 10:55:52 | D31: phoka@1pwrafrica.com | E31: In Progress | F31: it-support@1pwrafrica.com
A32: 58 | C32: 06/13/2022 11:22:09 | D32: cadkikine@gmail.com | E32: In Progress | F32: it-support@1pwrafrica.com
A33: 59 | C33: 06/13/2022 15:10:53 | D33: makoetje@1pwrafrica.com | E33: In Progress | F33: it-support@1pwrafrica.com
A34: 60 | C34: 06/14/2022 07:34:14 | D34: morema@1pwrafrica.com | E34: In Progress | F34: it-support@1pwrafrica.com
A35: 61 | C35: 06/14/2022 07:41:03 | D35: Ramatla@1pwrafrica.com | E35: In Progress | F35: it-support@1pwrafrica.com
A36: 62 | C36: 06/14/2022 09:44:56 | D36: molefe@1pwrafrica.com | E36: Approved | F36: it-support@1pwrafrica.com | G36: Approved | H36: Please communicate with Mme Molefi | I36: 06/14/2022 02:42:18
A37: 63 | C37: 06/15/2022 13:35:52 | D37: lichabajameswest@gmail.com | E37: Approved | F37: it-support@1pwrafrica.com | G37: Approved | I37: 06/15/2022 01:37:26
A38: 64 | C38: 06/15/2022 13:41:50 | D38: tkemathaba@gmail.com | E38: Rejected | F38: it-support@1pwrafrica.com | G38: Rejected | H38: You don't just decide this. Talk to your lead, IT does not deal with company finances also. | I38: 06/15/2022 01:46:25
A39: 65 | C39: 06/17/2022 07:25:09 | D39: monoane@1pwrafrica.com | E39: Approved | F39: it-support@1pwrafrica.com | G39: Approved | I39: 06/17/2022 07:43:30
A40: 66 | C40: 06/17/2022 07:59:50 | D40: monoane@1pwrafrica.com | E40: Approved | F40: it-support@1pwrafrica.com | G40: Approved | I40: 06/17/2022 09:08:57
...

Sheet Tickets
A1: Timestamp | B1: Email address | C1: Email Address | D1: Select your Department | E1: Priority | F1: Choose option you want to be helped on? | G1: Complaint Type | H1: Problem Description (e.g Laptop not connecting to the internet) | I1: Attachment (Optional) e.g Share a screenshot of the problem | J1: Item Requested | K1: What do you need for? | L1: Quantity | M1: Attachment (Optional) e.g Share a photo of items Checked out | N1: Full Names | O1: Respondent's Email Address | R1: Request # [DO NOT DELETE] | S1: Unique Request # [DO NOT DELETE] | T1: Unique Request # [DO NOT DELETE] | U1: Final Status [DO NOT DELETE] | V1: Final Status [DO NOT DELETE] | X1: Overall Status
A2: 44599.737 | C2: Kamohelo | D2: EE Department
A3: 44599.775 | B3: motebanglekhooana@gmail.com | C3: Motebang Lekhooana | D3: EE Department
A4: 44599.778 | B4: kamohelo0329@gmail.com | C4: Kamohelo Makaaka | D4: EE Department
A5: 44600.432 | B5: mohlomirasekeiti@gmail.com | C5: Rasekeiti Mohlomi | D5: Operations and Maintanance
A6: 44601.377 | B6: morema@1pwrafrica.com | C6: Morema Thabo Mafantiri | D6: EE Department
A7: 44601.493 | B7: motebanglekhooana@gmail.com | C7: Motebang Lekhooana | D7: EE Department | G7: Hardware, do not have a monitor also.
A8: 44608.378 | B8: motebanglekhooana@gmail.com | C8: Motebang Lekhooana | D8: EE Department | G8: VGA to HDMI Converter | H8: Would like to have the mentioned tool please
A9: 44608.385 | B9: lsmatsepe@gmail.com | C9: Lebalang Sophia Relebohile 'Makhotso Matsepe | D9: EE Department | G9: WIFI problem | H9: why do you hate me so, why can i never connect to the wifi? ha! Do i not deserve nice things also?
A10: 44609.352 | B10: lsmatsepe@gmail.com | C10: lebalang matsepe | D10: EE | G10: Tool Request | H10: I need MS office
A11: 44616.632 | B11: tums@1pwrafrica.com | C11: Tumelo Makhetha | D11: Project Management | G11: Email | H11: My 1pwr email only works when I'm logged in as a guest user on my chrome browser.
A12: 44617.666 | B12: david@1pwrafrica.com | C12: David Song | D12: Project Management | G12: Calendar | H12: When I get a calendar invite, I sometimes have an issue of a time showing up in my calendar that is different from the original sender's time. Also, this form should include a way to upload document. I could share an email that shows the issue or I could send a screen shot. Also, should you have a separate "department" for management?
A13: 44622.594 | B13: david@1pwrafrica.com | C13: David Song | D13: Project Management | G13: Calendar Time Zones | H13: Neo S sent me an invite shows in my outlook that it was set in Amman Jordan Time. But we checked his settings, and it's in Maseru time. Can you please check this? Our meeting is one hour off. I think maybe Moeketse changed the invite, and maybe that messed things up?
A14: 44623.428 | B14: david@1pwrafrica.com | C14: David Song | D14: Project Management | G14: Calendar | H14: I often get multiple responses to a calendar invite that I sent out. | I14: https://drive.google.com/open?id=1Nk0z0tde8cduNqGwj_qB2-6uqBLJkuUe
A15: 44624.419 | B15: phoka@1pwrafrica.com | C15: Phoka Raphoka | D15: Procurement | G15: Device Issue (laptop, tablet or mobile phone) | H15: I need to install Java & Asycuda World the LRA Portal that allows me to retrieve VAT 11 documents for all motor vehicles procured, I need admin login details on the laptop.
A16: 44627.502 | B16: palama@1pwrafrica.com | C16: Palama Kelepa | D16: Finance | G16: Email | H16: outlook error message: sending reported error (0x800CCC78), verify email in account properties: server responded: 452 space shortage, please try later
A17: 44641.526 | B17: serobanyane@1pwrafrica.com | C17: Neo Serobanyane | D17: Operations and Maintainance | G17: Device Issue (laptop, tablet or mobile phone) | H17: SMS gateway not functional, customers complain that when they sent call back to check their balance they don't get their balance and they say it's been a while now.
A18: 44641.528 | B18: serobanyane@1pwrafrica.com | C18: Neo Serobanyane | D18: Operations and Maintainance | G18: Device Issue (laptop, tablet or mobile phone) | H18: SMS gateway not functional. M-Pesa messages appear on the App but SMS gateway doesn't automatically credit customers as usual.
A19: 44641.53 | B19: serobanyane@1pwrafrica.com | C19: Neo Serobanyane | D19: Operations and Maintainance | G19: Device Issue (laptop, tablet or mobile phone) | H19: Some m-pesa transactions date and time on SMS gateway invalid and gateway not crediting customers.
A20: 44649.426 | B20: tums@1pwrafrica.com | C20: Tumelo | D20: Project Management | G20: Internet Issue | H20: Very very poor connectivity yesterday and today
A21: 44663.679 | B21: phoka@1pwrafrica.com | C21: Phoka Raphoka | D21: Procurement | G21: Email | H21: I am unable to send email they bounce back with the following message: "This message was created automatically by mail delivery software. A message that you sent could not be delivered to one or more of its recipients. This is a permanent error. The following address(es) failed: Domain 1pwrafrica.com has exceeded the max defers and failures per hour (150/150 (92%)) allowed. Message discarded"
A22: 44670.586 | B22: teboho@1pwrafrica.com | C22: TEBOHO NOKO | D22: Reticulation | G22: Email | H22: can not login to my emails, Screenshot attached | I22: https://drive.google.com/open?id=10MhZyDLQ3wml9LuB9ykhQ91TLoUWuOJr
A23: 44671.667 | B23: motebanglekhooana@gmail.com | C23: Motebang Lekhooana | D23: EE | F23: Complaint Ticket | G23: Device Issue (laptop, tablet or mobile phone) | H23: test
A24: 44671.669 | B24: motebanglekhooana@gmail.com | F24: Budget Request | J24: test | K24: test
A25: 44671.711 | B25: motebanglekhooana@gmail.com | F25: Budget Request | J25: test | K25: test
A26: 44672.486 | B26: cadkikine@gmail.com | C26: Cad | D26: EE | F26: Budget Request | J26: Charger | K26: Test
A27: 44672.594 | B27: cadkikine@gmail.com | C27: Tlhoks | D27: EE | F27: Budget Request | J27: test | K27: test
A28: 44672.609 | B28: cadkikine@gmail.com | C28: Test | D28: EE | F28: Complaint Ticket | G28: Test | H28: Test
A29: 44672.665 | B29: test@gmail.com | C29: Test | D29: Finance | F29: Budget Request | J29: Test | K29: Testing
A30: 44677.659 | B30: morema@1pwrafrica.com | C30: Morema | D30: EE | F30: Equipment Request | J30: mouse | K30: hakena mouse
A31: 44692.389 | B31: motebanglekhooana@gmail.com | C31: Motebang | D31: EE | F31: Equipment Request | J31: test | K31: test
A32: 44694.655 | B32: h@gmail.com | C32: Jos | D32: Finance | E32: High | F32: Equipment Request | J32: mouse | K32: testing
A33: 44699.345 | B33: deon@1pwrafrica.com | C33: Deon | D33: Production | E33: Medium | F33: Report Issue | G33: Clockify / HR Portal | H33: Please assist Kubutu using HR Portal to submit his timecards. The problem seems to be with OT, remarks and exceptions. He was unable to submit timecards for April and still can't submit for May. | I33: https://drive.google.com/open?id=1QoU3gPP-iIragUSSWaIUPcIm-uOtNsk3, https://drive.google.com/open?id=1OwKrAvkCaTZ_g7mh3E5WHblBWc0wF9hL
A34: 44699.458 | B34: deon@1pwrafrica.com | C34: Deon | D34: Production | E34: Medium | F34: Report Issue | G34: Internet Issue | H34: 1PWR2 Wifi in Production area had no internet access yesterday and today its not available at all.
A35: 44700.403 | B35: deon@1pwrafrica.com | C35: Deon | D35: Production | E35: Medium | F35: Report Issue | G35: Internet Issue | H35: Follow up on ticket #23 which was not solved as reported. Still no internet access. | I35: https://drive.google.com/open?id=1Sqg7lAWPi03A3yFZVM2uUVIRJ55ARDoa
A36: 44700.621 | B36: deon@1pwrafrica.com | C36: Deon | D36: Production | E36: Medium | F36: Report Issue | G36: Internet Issue | H36: 1PWR2 connection only worked for about one hour after Econet service. No internet access available currently.
A37: 44700.743 | B37: tums@1pwrafrica.com | C37: Tumelo | D37: Project Management | E37: High | F37: Equipment Request | J37: Laptop | K37: Everyday work for Mlanjeni. His personal laptop's performance is deteriorating by the week.
A38: 44701.561 | B38: david@1pwrafrica.com | C38: David Song | D38: Project Management | E38: Low | F38: Report Issue | G38: Web site | H38: the O&M JD link is broken (https://1pwrafrica.com/?post_type=job_listing&p=3235); also does this form need to be two pages?
A39: 44711.604 | B39: tumelo@1pwrafrica.com | C39: Tumelo | D39: Project Management | E39: Medium | F39: Report Issue | G39: Email | H39: When I open my email to log in, I a message saying: " Your connection is not private". A screen shot of the message is attached. | I39: https://drive.google.com/open?id=1By_JccXQUuHSiTEEvEtnPu3hwcCvbraP
A40: 44712.473 | B40: cadkikine@gmail.com | C40: cad | D40: EE | E40: Low | F40: Equipment Request | J40: Tablet | K40: test | R40: 30 | V40: Approved
...

Sheet Sheet11

Sheet Check out
A1: Timestamp | B1: Company ID | C1: Equipment Description | D1: Checked By | E1: Entry Number | F1: Counter in check in | G1: Availabilty State | H1: =Inventory!B:B -> Company ID
H2: =Inventory!B:B
H3: =Inventory!B:B -> OnM Deparment Desktop
H4: =Inventory!B:B -> LOG01
A5: 44727.381 | B5: Main 0374 | C5: Phone | D5: Phoka Raphoka | E5: 1 | F5: =countif('Check in'!B:B,B5) -> 1 | G5: =ifs(exact(E5,F5),"Available",F5>E5,"Check item out first",E5>F5,"Checked out") -> Available | H5: =Inventory!B:B -> LOG02
A6: 44727.383 | B6: Com 01 | C6: Committee phone | D6: Tumelo Makhakhe | E6: =countif(B:B,B6) -> 1 | F6: =countif('Check in'!B:B,B6) -> 1 | G6: =ifs(exact(E6,F6),"Available",F6>E6,"Check item out first",E6>F6,"Checked out") -> Available | H6: =Inventory!B:B -> LOG03
A7: 44727.386 | B7: Com 02 | C7: Committee phone | D7: Mongali Tlali | E7: =countif(B:B,B7) -> 1 | F7: =countif('Check in'!B:B,B7) -> 0 | G7: =ifs(exact(E7,F7),"Available",F7>E7,"Check item out first",E7>F7,"Checked out") -> Checked out | H7: =Inventory!B:B -> LOG04
A8: 44727.387 | B8: Com 03 | C8: Committee phone | D8: Phoka Raphoka | E8: =countif(B:B,B8) -> 1 | F8: =countif('Check in'!B:B,B8) -> 0 | G8: =ifs(exact(E8,F8),"Available",F8>E8,"Check item out first",E8>F8,"Checked out") -> Checked out | H8: =Inventory!B:B -> CHR01
A9: 44727.388 | B9: PMTEAM01 | C9: Laptop, Asus VivoBook X515JAB_X515JA | D9: Tumelo Makhakhe | E9: =countif(B:B,B9) -> 1 | F9: =countif('Check in'!B:B,B9) -> 0 | G9: =ifs(exact(E9,F9),"Available",F9>E9,"Check item out first",E9>F9,"Checked out") -> Checked out | H9: =Inventory!B:B -> CHR02
A10: 44727.389 | B10: PMTEAM02 | C10: Laptop, Asus VivoBook X515JAB_X515JA | D10: Mongali Tlali | E10: =countif(B:B,B10) -> 1 | F10: =countif('Check in'!B:B,B10) -> 0 | G10: =ifs(exact(E10,F10),"Available",F10>E10,"Check item out first",E10>F10,"Checked out") -> Checked out | H10: =Inventory!B:B -> CHR03
A11: 44727.39 | B11: EHS01 | C11: Laptop, Gateway GWTN156-1RG | D11: Maferete Moorosi | E11: =countif(B:B,B11) -> 1 | F11: =countif('Check in'!B:B,B11) -> 0 | G11: =ifs(exact(E11,F11),"Available",F11>E11,"Check item out first",E11>F11,"Checked out") -> Checked out | H11: =Inventory!B:B -> CHRO4
A12: 44727.393 | B12: EE001 | C12: Laptop, Dell Latitude | D12: Josias Molomo | E12: =countif(B:B,B12) -> 1 | F12: =countif('Check in'!B:B,B12) -> 0 | G12: =ifs(exact(E12,F12),"Available",F12>E12,"Check item out first",E12>F12,"Checked out") -> Checked out | H12: =Inventory!B:B -> KB01
A13: 44727.393 | B13: EE002 | C13: Laptop, Dell Latitude | D13: Thabo Monoto | E13: =countif(B:B,B13) -> 1 | F13: =countif('Check in'!B:B,B13) -> 0 | G13: =ifs(exact(E13,F13),"Available",F13>E13,"Check item out first",E13>F13,"Checked out") -> Checked out | H13: =Inventory!B:B -> KB02
A14: 44727.394 | B14: EE003 | C14: Laptop, Hp Elitebook 840 G3 | D14: Bokang Mothomotsoana | E14: =countif(B:B,B14) -> 1 | F14: =countif('Check in'!B:B,B14) -> 0 | G14: =ifs(exact(E14,F14),"Available",F14>E14,"Check item out first",E14>F14,"Checked out") -> Checked out | H14: =Inventory!B:B -> KB03
A15: 44727.395 | B15: EE004 | C15: Laptop, Dell Latitude | D15: Tumisang Mathaba | E15: =countif(B:B,B15) -> 1 | F15: =countif('Check in'!B:B,B15) -> 0 | G15: =ifs(exact(E15,F15),"Available",F15>E15,"Check item out first",E15>F15,"Checked out") -> Checked out | H15: =Inventory!B:B -> KB04
A16: 44727.396 | B16: EE005 | C16: Laptop, Dell Latitude | D16: Motebang Lekhooana | E16: =countif(B:B,B16) -> 1 | F16: =countif('Check in'!B:B,B16) -> 0 | G16: =ifs(exact(E16,F16),"Available",F16>E16,"Check item out first",E16>F16,"Checked out") -> Checked out | H16: =Inventory!B:B -> CP01
A17: 44727.399 | B17: 0080 | C17: Monitor, Hikvision | D17: Finance office | E17: =countif(B:B,B17) -> 1 | F17: =countif('Check in'!B:B,B17) -> 0 | G17: =ifs(exact(E17,F17),"Available",F17>E17,"Check item out first",E17>F17,"Checked out") -> Checked out | H17: =Inventory!B:B -> CP02
H18: =Inventory!B:B -> CP03
A19: 44727.404 | B19: AD002 | C19: Monitor,Telefunken TLEDD-24HD | D19: Refiloe Ramalefane | E19: =countif(B:B,B19) -> 1 | F19: =countif('Check in'!B:B,B19) -> 0 | G19: =ifs(exact(E19,F19),"Available",F19>E19,"Check item out first",E19>F19,"Checked out") -> Checked out | H19: =Inventory!B:B -> CP04
A20: 44727.404 | B20: AD003 | C20: Monitor, Telefunken TLEDD-24HD | D20: Moliehi Lepheane | E20: =countif(B:B,B20) -> 1 | F20: =countif('Check in'!B:B,B20) -> 0 | G20: =ifs(exact(E20,F20),"Available",F20>E20,"Check item out first",E20>F20,"Checked out") -> Checked out | H20: =Inventory!B:B -> LDS00
A21: 44727.406 | B21: EE01 | C21: Monitor, Dell S2421HN | D21: Josias Molomo | E21: =countif(B:B,B21) -> 1 | F21: =countif('Check in'!B:B,B21) -> 0 | G21: =ifs(exact(E21,F21),"Available",F21>E21,"Check item out first",E21>F21,"Checked out") -> Checked out | H21: =Inventory!B:B -> RBP00
A22: 44727.416 | B22: EE02 | C22: Monitor, Dell S2421HN | D22: Motlatsi Manka | E22: =countif(B:B,B22) -> 1 | F22: =countif('Check in'!B:B,B22) -> 0 | G22: =ifs(exact(E22,F22),"Available",F22>E22,"Check item out first",E22>F22,"Checked out") -> Checked out | H22: =Inventory!B:B -> SML001
A23: 44727.417 | B23: EE03 | C23: Monitor, Dell S2421HN | D23: Bokang Mothomotsoana | E23: =countif(B:B,B23) -> 1 | F23: =countif('Check in'!B:B,B23) -> 0 | G23: =ifs(exact(E23,F23),"Available",F23>E23,"Check item out first",E23>F23,"Checked out") -> Checked out | H23: =Inventory!B:B -> SML002
A24: 44727.42 | B24: EE04 | C24: Monitor, Samsung | D24: Tumisang Mathaba | E24: =countif(B:B,B24) -> 1 | F24: =countif('Check in'!B:B,B24) -> 0 | G24: =ifs(exact(E24,F24),"Available",F24>E24,"Check item out first",E24>F24,"Checked out") -> Checked out | H24: =Inventory!B:B -> SML003
A25: 44727.424 | B25: EE05 | C25: Monitor, Dell S2421HN | D25: Motebang Lekhooana | E25: =countif(B:B,B25) -> 1 | F25: =countif('Check in'!B:B,B25) -> 0 | G25: =ifs(exact(E25,F25),"Available",F25>E25,"Check item out first",E25>F25,"Checked out") -> Checked out | H25: =Inventory!B:B -> SML004
A26: 44727.424 | B26: EE06 | C26: Monitor, Dell S2421HN | D26: Thabang Hatlane | E26: =countif(B:B,B26) -> 1 | F26: =countif('Check in'!B:B,B26) -> 0 | G26: =ifs(exact(E26,F26),"Available",F26>E26,"Check item out first",E26>F26,"Checked out") -> Checked out | H26: =Inventory!B:B -> SML 005
A27: 44727.425 | B27: EE07 | C27: Monitor, Dell S2421HN | D27: Morema Mafantiri | E27: =countif(B:B,B27) -> 1 | F27: =countif('Check in'!B:B,B27) -> 0 | G27: =ifs(exact(E27,F27),"Available",F27>E27,"Check item out first",E27>F27,"Checked out") -> Checked out | H27: =Inventory!B:B -> PMP001
A28: 44727.426 | B28: EE08 | C28: Monitor, Samsung | D28: Lichaba West | E28: =countif(B:B,B28) -> 1 | F28: =countif('Check in'!B:B,B28) -> 0 | G28: =ifs(exact(E28,F28),"Available",F28>E28,"Check item out first",E28>F28,"Checked out") -> Checked out | H28: =Inventory!B:B -> BULB001
A29: 44727.426 | B29: EE09 | C29: Monitor, ViewSonic | D29: Tsabalira Phoofolo | E29: =countif(B:B,B29) -> 1 | F29: =countif('Check in'!B:B,B29) -> 0 | G29: =ifs(exact(E29,F29),"Available",F29>E29,"Check item out first",E29>F29,"Checked out") -> Checked out | H29: =Inventory!B:B -> Untagged/None
A30: 44727.427 | B30: 0444 | C30: Monitor, Telefunken | D30: O&M | E30: =countif(B:B,B30) -> 2 | F30: 1 | G30: =ifs(exact(E30,F30),"Available",F30>E30,"Check item out first",E30>F30,"Checked out") -> Checked out | H30: =Inventory!B:B -> Surf -1
A31: 44727.427 | B31: 0420 | C31: Monitor, Telefunken | D31: Neo Serobanyane | E31: =countif(B:B,B31) -> 2 | F31: =countif('Check in'!B:B,B31) -> 1 | G31: =ifs(exact(E31,F31),"Available",F31>E31,"Check item out first",E31>F31,"Checked out") -> Checked out | H31: =Inventory!B:B -> Main
A32: 44727.429 | B32: 0381-B | C32: Monitor, ViewSonic | D32: Jonas Nthunya | E32: =countif(B:B,B32) -> 2 | F32: =countif('Check in'!B:B,B32) -> 1 | G32: =ifs(exact(E32,F32),"Available",F32>E32,"Check item out first",E32>F32,"Checked out") -> Checked out | H32: =Inventory!B:B -> X-trail Phone
A33: 44727.435 | B33: AD001 | C33: Monitor, Dell S2421HN | D33: Palama Kelepa | E33: =countif(B:B,B33) -> 1 | F33: =countif('Check in'!B:B,B33) -> 0 | G33: =ifs(exact(E33,F33),"Available",F33>E33,"Check item out first",E33>F33,"Checked out") -> Checked out | H33: =Inventory!B:B -> Truck 36 Phone
A34: 44727.436 | B34: EHS-10 | C34: Monitor, Dell S2421HN | D34: Kekeletso Rakoti | E34: =countif(B:B,B34) -> 1 | F34: =countif('Check in'!B:B,B34) -> 0 | G34: =ifs(exact(E34,F34),"Available",F34>E34,"Check item out first",E34>F34,"Checked out") -> Checked out | H34: =Inventory!B:B -> SMS gateway
A35: 44727.437 | B35: 0441 | C35: Laptop, Dell | D35: Nthabiseng Thakhisi | E35: =countif(B:B,B35) -> 2 | F35: =countif('Check in'!B:B,B35) -> 1 | G35: =ifs(exact(E35,F35),"Available",F35>E35,"Check item out first",E35>F35,"Checked out") -> Checked out | H35: =Inventory!B:B -> Dev & Test Phone
A36: 44727.441 | B36: AD-1 | C36: Switch, HiLook | D36: Finance office | E36: =countif(B:B,B36) -> 1 | F36: =countif('Check in'!B:B,B36) -> 0 | G36: =ifs(exact(E36,F36),"Available",F36>E36,"Check item out first",E36>F36,"Checked out") -> Checked out | H36: =Inventory!B:B -> Makebe Field Site 0363
A37: 44727.446 | B37: AD-2 | C37: Router, ZTE | D37: Finance office | E37: =countif(B:B,B37) -> 1 | F37: =countif('Check in'!B:B,B37) -> 0 | G37: =ifs(exact(E37,F37),"Available",F37>E37,"Check item out first",E37>F37,"Checked out") -> Checked out | H37: =Inventory!B:B -> Survey Phone 0369
A38: 44727.446 | B38: AD-3 | C38: Phone,iServe | D38: Finance office | E38: =countif(B:B,B38) -> 1 | F38: =countif('Check in'!B:B,B38) -> 0 | G38: =ifs(exact(E38,F38),"Available",F38>E38,"Check item out first",E38>F38,"Checked out") -> Checked out | H38: =Inventory!B:B -> Survey Phone 0370
A39: 44727.651 | B39: RET 04 | C39: Hp Laptop,Charger | D39: Lichaba West | E39: 2 | F39: =countif('Check in'!B:B,B39) -> 2 | G39: =ifs(exact(E39,F39),"Available",F39>E39,"Check item out first",E39>F39,"Checked out") -> Available | H39: =Inventory!B:B -> Pajero
A40: 44810.611 | B40: Untagged/None | C40: Power Bank | D40: Tumisang Mathaba | E40: 2 | F40: =countif('Check in'!B:B,B40) -> 0 | G40: =ifs(exact(E40,F40),"Available",F40>E40,"Check item out first",E40>F40,"Checked out") -> Checked out | H40: =Inventory!B:B -> Surf -2 0373
...

Sheet Check in
A1: Timestamp | B1: Company ID | C1: Returned by | D1: Condition
A3: 44725.697 | B3: Surf -1 | C3: test
A4: 44726.368 | B4: Main 0374 | C4: Tumelo
A6: 44728.404 | B6: Truck 36 Phone | C6: Tlhokomelo
A7: 44728.458 | B7: SMS gateway | C7: testing | D7: Needs Maintainance
A8: 44728.536 | B8: X-trail Phone | C8: testing | D8: Good Condition
A9: 44728.536 | B9: Dev & Test Phone | C9: testing | D9: Needs Repair
A10: 44728.537 | B10: Pajero | C10: testing | D10: Unrepairable
A11: 44729.628 | B11: RET 04 | C11: Lichaba West | D11: Good Condition
A12: 44812.631 | C12: Kekeletso Rakoti | D12: Good Condition
B13: SMS gateway
B14: Dev & Test Phone
B15: Makebe Field Site 0363
B16: Survey Phone 0369
B17: Survey Phone 0370
B18: Pajero
B19: Surf -2 0373
B20: Customer Support
B21: Com 01 | C21: test | D21: good condition
B22: MOD0001 | C22: Matete | D22: good condition
B23: MODUSB0002 | C23: Matete | D23: good condition
B45: Com 25
B66: 006
B67: 009
B70: 008
B71: 0365
B74: New02
B80: RET 01
B81: RET 02
B82: RET 03
B83: RET 04
B84: RET 05
B85: RET 06
... B187: RET0023

Sheet Waste
A1: Item | B1: Quantity
A2: Tablets | B2: 5
A3: Laptop Battery | B3: 1
A4: Phone Battery | B4: 1

Sheet Total
A1: Available | D1: EE | E1: HR | F1: Finance | G1: O&M | H1: EHS | I1: Procurement | J1: Production | K1: Fleet | L1: Project Management | M1: Reticulation | N1: Pueco
A2: Laptops | B2: =COUNTIF(Inventory!E:E,"Laptop") -> 27 | D2: =COUNTIFS(Inventory!E:E,"Laptop",Inventory!M:M,"EE") -> 6 | E2: =COUNTIFS(Inventory!E:E,"Laptop",Inventory!M:M,"Human Resources") -> 0 | F2: =COUNTIFS(Inventory!E:E,"Laptop",Inventory!M:M,"Finance") -> 1 | G2: =COUNTIFS(Inventory!E:E,"Laptop",Inventory!M:M,"Operations and Maintenance") -> 0 | H2: =COUNTIFS(Inventory!E:E,"Laptop",Inventory!M:M,"EHS") -> 1 | I2: =COUNTIFS(Inventory!E:E,"Laptop",Inventory!M:M,"Procurement") -> 0 | J2: =COUNTIFS(Inventory!E:E,"Laptop",Inventory!M:M,"Production") -> 0 | K2: 1 | L2: =COUNTIFS(Inventory!E:E,"Laptop",Inventory!M:M,"Project Management") -> 3 | M2: =COUNTIFS(Inventory!E:E,"Laptop",Inventory!M:M,"Reticulation") -> 10 | N2: =COUNTIFS(Inventory!E:E,"Laptop",Inventory!M:M,"Pueco") -> 0
A3: Phones | B3: =COUNTIF(Inventory!E:E,"Phone") -> 59 | D3: =COUNTIFS(Inventory!E:E,"Phone",Inventory!M:M,"EE") -> 0 | E3: =COUNTIFS(Inventory!E:E,"Phone",Inventory!M:M,"Human Resources") -> 0 | F3: =COUNTIFS(Inventory!E:E,"Phone",Inventory!M:M,"Finance") -> 0 | G3: =COUNTIFS(Inventory!E:E,"Phone",Inventory!M:M,"Operations and Maintenance") -> 0 | H3: =COUNTIFS(Inventory!E:E,"Phone",Inventory!M:M,"EHS") -> 1 | I3: =COUNTIFS(Inventory!E:E,"Phone",Inventory!M:M,"Procurement") -> 1 | J3: =COUNTIFS(Inventory!E:E,"Phone",Inventory!M:M,"Production") -> 0 | K3: 1 | L3: =COUNTIFS(Inventory!E:E,"Phone",Inventory!M:M,"Project Management") -> 42 | M3: =COUNTIFS(Inventory!E:E,"Phone",Inventory!M:M,"Reticulation") -> 2 | N3: =COUNTIFS(Inventory!E:E,"Phone",Inventory!M:M,"Pueco") -> 0
A4: Desktops | B4: =COUNTIF(Inventory!E:E,"Monitor") -> 20 | D4: =COUNTIFS(Inventory!E:E,"Monitor",Inventory!M:M,"EE") -> 7 | E4: =COUNTIFS(Inventory!E:E,"Monitor",Inventory!M:M,"Human Resources") -> 0 | F4: =COUNTIFS(Inventory!E:E,"Monitor",Inventory!M:M,"Finance") -> 4 | G4: =COUNTIFS(Inventory!E:E,"Monitor",Inventory!M:M,"Operations and Maintenance") -> 2 | H4: =COUNTIFS(Inventory!E:E,"Monitor",Inventory!M:M,"EHS") -> 1 | I4: =COUNTIFS(Inventory!E:E,"Monitor",Inventory!M:M,"Procurement") -> 2 | J4: =COUNTIFS(Inventory!E:E,"Monitor",Inventory!M:M,"Production") -> 0 | K4: =COUNTIFS(Inventory!E:E,"Monitor",Inventory!M:M,"Fleet") -> 0 | L4: =COUNTIFS(Inventory!E:E,"Monitor",Inventory!M:M,"Project Management") -> 2 | M4: =COUNTIFS(Inventory!E:E,"Monitor",Inventory!M:M,"Reticulation") -> 0 | N4: =COUNTIFS(Inventory!E:E,"Monitor",Inventory!M:M,"Pueco") -> 0
A5: Tablets | B5: =COUNTIF(Inventory!E:E,"Tablet") -> 13 | D5: =COUNTIFS(Inventory!E:E,"Tablet",Inventory!M:M,"EE") -> 1 | E5: =COUNTIFS(Inventory!E:E,"Tablet",Inventory!M:M,"Human Resources") -> 0 | F5: =COUNTIFS(Inventory!E:E,"Tablet",Inventory!M:M,"Finance") -> 0 | G5: =COUNTIFS(Inventory!E:E,"Tablet",Inventory!M:M,"Operations and Maintenance") -> 0 | H5: =COUNTIFS(Inventory!E:E,"Tablet",Inventory!M:M,"EHS") -> 12 | I5: =COUNTIFS(Inventory!E:E,"Tablet",Inventory!M:M,"Procurement") -> 0 | J5: =COUNTIFS(Inventory!E:E,"Tablet",Inventory!M:M,"Production") -> 0 | K5: =COUNTIFS(Inventory!E:E,"Tablet",Inventory!M:M,"Fleet") -> 0 | L5: =COUNTIFS(Inventory!E:E,"Tablet",Inventory!M:M,"Project Management") -> 0 | M5: =COUNTIFS(Inventory!E:E,"Tablet",Inventory!M:M,"Reticulation") -> 0 | N5: =COUNTIFS(Inventory!E:E,"Tablet",Inventory!M:M,"Pueco") -> 0
